2021-08-15 16:56:28,677 - util.py[DEBUG]: Cloud-init v. 20.2-45-g5f7825e2-0ubuntu1~18.04.1 running 'init-local' at Sun, 15 Aug 2021 16:56:28 +0000. Up 9.03 seconds.
2021-08-15 16:56:28,677 - main.py[DEBUG]: No kernel command line url found.
2021-08-15 16:56:28,677 - main.py[DEBUG]: Closing stdin.
2021-08-15 16:56:28,679 - util.py[DEBUG]: Writing to /var/log/cloud-init.log - ab: [644] 0 bytes
2021-08-15 16:56:28,680 - util.py[DEBUG]: Changing the ownership of /var/log/cloud-init.log to 102:4
2021-08-15 16:56:28,680 - util.py[DEBUG]: Attempting to remove /var/lib/cloud/instance/boot-finished
2021-08-15 16:56:28,680 - util.py[DEBUG]: Attempting to remove /var/lib/cloud/data/no-net
2021-08-15 16:56:28,680 - handlers.py[DEBUG]: start: init-local/check-cache: attempting to read from cache [check]
2021-08-15 16:56:28,680 - util.py[DEBUG]: Reading from /var/lib/cloud/instance/obj.pkl (quiet=False)
2021-08-15 16:56:28,680 - stages.py[DEBUG]: no cache found
2021-08-15 16:56:28,680 - handlers.py[DEBUG]: finish: init-local/check-cache: SUCCESS: no cache found
2021-08-15 16:56:28,680 - util.py[DEBUG]: Attempting to remove /var/lib/cloud/instance
2021-08-15 16:56:28,684 - stages.py[DEBUG]: Using distro class <class 'cloudinit.distros.ubuntu.Distro'>
2021-08-15 16:56:28,684 - __init__.py[DEBUG]: Looking for data source in: ['None'], via packages ['', 'cloudinit.sources'] that matches dependencies ['FILESYSTEM']
2021-08-15 16:56:28,685 - __init__.py[DEBUG]: Searching for local data source in: []
2021-08-15 16:56:28,685 - main.py[DEBUG]: No local datasource found
2021-08-15 16:56:28,687 - util.py[DEBUG]: Reading from /etc/os-release (quiet=False)
2021-08-15 16:56:28,687 - util.py[DEBUG]: Read 386 bytes from /etc/os-release
2021-08-15 16:56:28,687 - util.py[DEBUG]: Reading from /sys/class/net/lo/address (quiet=False)
2021-08-15 16:56:28,687 - util.py[DEBUG]: Read 18 bytes from /sys/class/net/lo/address
2021-08-15 16:56:28,687 - util.py[DEBUG]: Reading from /sys/class/net/enp0s3/address (quiet=False)
2021-08-15 16:56:28,687 - util.py[DEBUG]: Read 18 bytes from /sys/class/net/enp0s3/address
2021-08-15 16:56:28,687 - stages.py[DEBUG]: network config disabled by system_cfg
2021-08-15 16:56:28,688 - stages.py[INFO]: network config is disabled by system_cfg
2021-08-15 16:56:28,688 - main.py[DEBUG]: [local] Exiting without datasource
2021-08-15 16:56:28,688 - atomic_helper.py[DEBUG]: Atomically writing to file /var/lib/cloud/data/status.json (via temporary file /var/lib/cloud/data/tmp4ursys8u) - w: [644] 474 bytes/chars
2021-08-15 16:56:28,688 - util.py[DEBUG]: Reading from /proc/uptime (quiet=False)
2021-08-15 16:56:28,688 - util.py[DEBUG]: Read 10 bytes from /proc/uptime
2021-08-15 16:56:28,688 - util.py[DEBUG]: cloud-init mode 'init' took 0.058 seconds (0.05)
2021-08-15 16:56:28,688 - handlers.py[DEBUG]: finish: init-local: SUCCESS: searching for local datasources
2021-08-15 16:56:30,376 - util.py[DEBUG]: Cloud-init v. 20.2-45-g5f7825e2-0ubuntu1~18.04.1 running 'init' at Sun, 15 Aug 2021 16:56:30 +0000. Up 10.74 seconds.
2021-08-15 16:56:30,376 - main.py[DEBUG]: No kernel command line url found.
2021-08-15 16:56:30,376 - main.py[DEBUG]: Closing stdin.
2021-08-15 16:56:30,377 - util.py[DEBUG]: Writing to /var/log/cloud-init.log - ab: [644] 0 bytes
2021-08-15 16:56:30,378 - util.py[DEBUG]: Changing the ownership of /var/log/cloud-init.log to 102:4
2021-08-15 16:56:30,378 - util.py[DEBUG]: Reading from /etc/os-release (quiet=False)
2021-08-15 16:56:30,379 - util.py[DEBUG]: Read 386 bytes from /etc/os-release
2021-08-15 16:56:30,380 - util.py[DEBUG]: Running command ['ip', 'addr', 'show'] with allowed return codes [0] (shell=False, capture=True)
2021-08-15 16:56:30,395 - util.py[DEBUG]: Running command ['ip', '-o', 'route', 'list'] with allowed return codes [0] (shell=False, capture=True)
2021-08-15 16:56:30,398 - util.py[DEBUG]: Running command ['ip', '--oneline', '-6', 'route', 'list', 'table', 'all'] with allowed return codes [0, 1] (shell=False, capture=True)
2021-08-15 16:56:30,402 - main.py[DEBUG]: Checking to see if files that we need already exist from a previous run that would allow us to stop early.
2021-08-15 16:56:30,402 - main.py[DEBUG]: Execution continuing, no previous run detected that would allow us to stop early.
2021-08-15 16:56:30,402 - handlers.py[DEBUG]: start: init-network/check-cache: attempting to read from cache [trust]
2021-08-15 16:56:30,402 - util.py[DEBUG]: Reading from /var/lib/cloud/instance/obj.pkl (quiet=False)
2021-08-15 16:56:30,402 - stages.py[DEBUG]: no cache found
2021-08-15 16:56:30,402 - handlers.py[DEBUG]: finish: init-network/check-cache: SUCCESS: no cache found
2021-08-15 16:56:30,402 - util.py[DEBUG]: Attempting to remove /var/lib/cloud/instance
2021-08-15 16:56:30,420 - stages.py[DEBUG]: Using distro class <class 'cloudinit.distros.ubuntu.Distro'>
2021-08-15 16:56:30,420 - __init__.py[DEBUG]: Looking for data source in: ['None'], via packages ['', 'cloudinit.sources'] that matches dependencies ['FILESYSTEM', 'NETWORK']
2021-08-15 16:56:30,421 - __init__.py[DEBUG]: Searching for network data source in: ['DataSourceNone']
2021-08-15 16:56:30,421 - handlers.py[DEBUG]: start: init-network/search-None: searching for network data from DataSourceNone
2021-08-15 16:56:30,421 - __init__.py[DEBUG]: Seeing if we can get any data from <class 'cloudinit.sources.DataSourceNone.DataSourceNone'>
2021-08-15 16:56:30,421 - __init__.py[DEBUG]: Update datasource metadata and network config due to events: New instance first boot
2021-08-15 16:56:30,421 - util.py[DEBUG]: Reading from /etc/hosts (quiet=False)
2021-08-15 16:56:30,421 - util.py[DEBUG]: Read 222 bytes from /etc/hosts
2021-08-15 16:56:30,422 - atomic_helper.py[DEBUG]: Atomically writing to file /run/cloud-init/instance-data-sensitive.json (via temporary file /run/cloud-init/tmp0h9jpqws) - w: [600] 5106 bytes/chars
2021-08-15 16:56:30,422 - atomic_helper.py[DEBUG]: Atomically writing to file /run/cloud-init/instance-data.json (via temporary file /run/cloud-init/tmplbe4mfpx) - w: [644] 1407 bytes/chars
2021-08-15 16:56:30,423 - handlers.py[DEBUG]: finish: init-network/search-None: SUCCESS: found network data from DataSourceNone
2021-08-15 16:56:30,423 - stages.py[INFO]: Loaded datasource DataSourceNone - DataSourceNone
2021-08-15 16:56:30,423 - util.py[DEBUG]: Reading from /etc/cloud/cloud.cfg (quiet=False)
2021-08-15 16:56:30,423 - util.py[DEBUG]: Read 3517 bytes from /etc/cloud/cloud.cfg
2021-08-15 16:56:30,423 - util.py[DEBUG]: Attempting to load yaml from string of length 3517 with allowed root types (<class 'dict'>,)
2021-08-15 16:56:30,432 - util.py[DEBUG]: Reading from /etc/cloud/cloud.cfg.d/subiquity-disable-cloudinit-networking.cfg (quiet=False)
2021-08-15 16:56:30,432 - util.py[DEBUG]: Read 28 bytes from /etc/cloud/cloud.cfg.d/subiquity-disable-cloudinit-networking.cfg
2021-08-15 16:56:30,432 - util.py[DEBUG]: Attempting to load yaml from string of length 28 with allowed root types (<class 'dict'>,)
2021-08-15 16:56:30,432 - util.py[DEBUG]: Reading from /etc/cloud/cloud.cfg.d/curtin-preserve-sources.cfg (quiet=False)
2021-08-15 16:56:30,432 - util.py[DEBUG]: Read 35 bytes from /etc/cloud/cloud.cfg.d/curtin-preserve-sources.cfg
2021-08-15 16:56:30,432 - util.py[DEBUG]: Attempting to load yaml from string of length 35 with allowed root types (<class 'dict'>,)
2021-08-15 16:56:30,433 - util.py[DEBUG]: Reading from /etc/cloud/cloud.cfg.d/99-installer.cfg (quiet=False)
2021-08-15 16:56:30,433 - util.py[DEBUG]: Read 543 bytes from /etc/cloud/cloud.cfg.d/99-installer.cfg
2021-08-15 16:56:30,433 - util.py[DEBUG]: Attempting to load yaml from string of length 543 with allowed root types (<class 'dict'>,)
2021-08-15 16:56:30,434 - util.py[DEBUG]: Reading from /etc/cloud/cloud.cfg.d/90_dpkg.cfg (quiet=False)
2021-08-15 16:56:30,434 - util.py[DEBUG]: Read 277 bytes from /etc/cloud/cloud.cfg.d/90_dpkg.cfg
2021-08-15 16:56:30,434 - util.py[DEBUG]: Attempting to load yaml from string of length 277 with allowed root types (<class 'dict'>,)
2021-08-15 16:56:30,435 - util.py[DEBUG]: Reading from /etc/cloud/cloud.cfg.d/05_logging.cfg (quiet=False)
2021-08-15 16:56:30,436 - util.py[DEBUG]: Read 2057 bytes from /etc/cloud/cloud.cfg.d/05_logging.cfg
2021-08-15 16:56:30,436 - util.py[DEBUG]: Attempting to load yaml from string of length 2057 with allowed root types (<class 'dict'>,)
2021-08-15 16:56:30,439 - util.py[DEBUG]: Reading from /run/cloud-init/cloud.cfg (quiet=False)
2021-08-15 16:56:30,439 - util.py[DEBUG]: Attempting to load yaml from string of length 0 with allowed root types (<class 'dict'>,)
2021-08-15 16:56:30,439 - util.py[DEBUG]: loaded blob returned None, returning default.
2021-08-15 16:56:30,439 - util.py[DEBUG]: Attempting to remove /var/lib/cloud/instance
2021-08-15 16:56:30,439 - util.py[DEBUG]: Creating symbolic link from '/var/lib/cloud/instance' => '/var/lib/cloud/instances/iid-datasource-none'
2021-08-15 16:56:30,440 - util.py[DEBUG]: Reading from /var/lib/cloud/instances/iid-datasource-none/datasource (quiet=False)
2021-08-15 16:56:30,440 - util.py[DEBUG]: Writing to /var/lib/cloud/instances/iid-datasource-none/datasource - wb: [644] 31 bytes
2021-08-15 16:56:30,440 - util.py[DEBUG]: Writing to /var/lib/cloud/data/previous-datasource - wb: [644] 31 bytes
2021-08-15 16:56:30,441 - util.py[DEBUG]: Reading from /var/lib/cloud/data/instance-id (quiet=False)
2021-08-15 16:56:30,441 - stages.py[DEBUG]: previous iid found to be NO_PREVIOUS_INSTANCE_ID
2021-08-15 16:56:30,441 - util.py[DEBUG]: Writing to /var/lib/cloud/data/instance-id - wb: [644] 20 bytes
2021-08-15 16:56:30,441 - util.py[DEBUG]: Writing to /run/cloud-init/.instance-id - wb: [644] 20 bytes
2021-08-15 16:56:30,441 - util.py[DEBUG]: Writing to /var/lib/cloud/data/previous-instance-id - wb: [644] 24 bytes
2021-08-15 16:56:30,442 - util.py[DEBUG]: Writing to /var/lib/cloud/instance/obj.pkl - wb: [400] 6693 bytes
2021-08-15 16:56:30,442 - main.py[DEBUG]: [net] init will now be targeting instance id: iid-datasource-none. new=True
2021-08-15 16:56:30,442 - util.py[DEBUG]: Reading from /etc/cloud/cloud.cfg (quiet=False)
2021-08-15 16:56:30,442 - util.py[DEBUG]: Read 3517 bytes from /etc/cloud/cloud.cfg
2021-08-15 16:56:30,442 - util.py[DEBUG]: Attempting to load yaml from string of length 3517 with allowed root types (<class 'dict'>,)
2021-08-15 16:56:30,452 - util.py[DEBUG]: Reading from /etc/cloud/cloud.cfg.d/subiquity-disable-cloudinit-networking.cfg (quiet=False)
2021-08-15 16:56:30,452 - util.py[DEBUG]: Read 28 bytes from /etc/cloud/cloud.cfg.d/subiquity-disable-cloudinit-networking.cfg
2021-08-15 16:56:30,452 - util.py[DEBUG]: Attempting to load yaml from string of length 28 with allowed root types (<class 'dict'>,)
2021-08-15 16:56:30,452 - util.py[DEBUG]: Reading from /etc/cloud/cloud.cfg.d/curtin-preserve-sources.cfg (quiet=False)
2021-08-15 16:56:30,452 - util.py[DEBUG]: Read 35 bytes from /etc/cloud/cloud.cfg.d/curtin-preserve-sources.cfg
2021-08-15 16:56:30,452 - util.py[DEBUG]: Attempting to load yaml from string of length 35 with allowed root types (<class 'dict'>,)
2021-08-15 16:56:30,453 - util.py[DEBUG]: Reading from /etc/cloud/cloud.cfg.d/99-installer.cfg (quiet=False)
2021-08-15 16:56:30,453 - util.py[DEBUG]: Read 543 bytes from /etc/cloud/cloud.cfg.d/99-installer.cfg
2021-08-15 16:56:30,453 - util.py[DEBUG]: Attempting to load yaml from string of length 543 with allowed root types (<class 'dict'>,)
2021-08-15 16:56:30,454 - util.py[DEBUG]: Reading from /etc/cloud/cloud.cfg.d/90_dpkg.cfg (quiet=False)
2021-08-15 16:56:30,454 - util.py[DEBUG]: Read 277 bytes from /etc/cloud/cloud.cfg.d/90_dpkg.cfg
2021-08-15 16:56:30,454 - util.py[DEBUG]: Attempting to load yaml from string of length 277 with allowed root types (<class 'dict'>,)
2021-08-15 16:56:30,455 - util.py[DEBUG]: Reading from /etc/cloud/cloud.cfg.d/05_logging.cfg (quiet=False)
2021-08-15 16:56:30,455 - util.py[DEBUG]: Read 2057 bytes from /etc/cloud/cloud.cfg.d/05_logging.cfg
2021-08-15 16:56:30,455 - util.py[DEBUG]: Attempting to load yaml from string of length 2057 with allowed root types (<class 'dict'>,)
2021-08-15 16:56:30,458 - util.py[DEBUG]: Reading from /run/cloud-init/cloud.cfg (quiet=False)
2021-08-15 16:56:30,458 - util.py[DEBUG]: Attempting to load yaml from string of length 0 with allowed root types (<class 'dict'>,)
2021-08-15 16:56:30,458 - util.py[DEBUG]: loaded blob returned None, returning default.
2021-08-15 16:56:30,459 - util.py[DEBUG]: Reading from /sys/class/net/lo/address (quiet=False)
2021-08-15 16:56:30,459 - util.py[DEBUG]: Read 18 bytes from /sys/class/net/lo/address
2021-08-15 16:56:30,459 - util.py[DEBUG]: Reading from /sys/class/net/enp0s3/address (quiet=False)
2021-08-15 16:56:30,459 - util.py[DEBUG]: Read 18 bytes from /sys/class/net/enp0s3/address
2021-08-15 16:56:30,459 - stages.py[DEBUG]: network config disabled by system_cfg
2021-08-15 16:56:30,459 - stages.py[INFO]: network config is disabled by system_cfg
2021-08-15 16:56:30,459 - handlers.py[DEBUG]: start: init-network/setup-datasource: setting up datasource
2021-08-15 16:56:30,459 - handlers.py[DEBUG]: finish: init-network/setup-datasource: SUCCESS: setting up datasource
2021-08-15 16:56:30,459 - util.py[DEBUG]: Writing to /var/lib/cloud/instances/iid-datasource-none/user-data.txt - wb: [600] 363 bytes
2021-08-15 16:56:30,460 - util.py[DEBUG]: Attempting to load yaml from string of length 363 with allowed root types (<class 'dict'>,)
2021-08-15 16:56:30,464 - util.py[DEBUG]: Writing to /var/lib/cloud/instances/iid-datasource-none/user-data.txt.i - wb: [600] 668 bytes
2021-08-15 16:56:30,464 - util.py[DEBUG]: Writing to /var/lib/cloud/instances/iid-datasource-none/vendor-data.txt - wb: [600] 0 bytes
2021-08-15 16:56:30,465 - util.py[DEBUG]: Writing to /var/lib/cloud/instances/iid-datasource-none/vendor-data.txt.i - wb: [600] 308 bytes
2021-08-15 16:56:30,466 - stages.py[DEBUG]: Using distro class <class 'cloudinit.distros.ubuntu.Distro'>
2021-08-15 16:56:30,466 - util.py[DEBUG]: Writing to /var/lib/cloud/instances/iid-datasource-none/sem/consume_data - wb: [644] 24 bytes
2021-08-15 16:56:30,467 - helpers.py[DEBUG]: Running consume_data using lock (<FileLock using file '/var/lib/cloud/instances/iid-datasource-none/sem/consume_data'>)
2021-08-15 16:56:30,467 - handlers.py[DEBUG]: start: init-network/consume-user-data: reading and applying user-data
2021-08-15 16:56:30,467 - stages.py[DEBUG]: Added default handler for {'text/cloud-config', 'text/cloud-config-jsonp'} from CloudConfigPartHandler: [['text/cloud-config', 'text/cloud-config-jsonp']]
2021-08-15 16:56:30,467 - stages.py[DEBUG]: Added default handler for {'text/x-shellscript'} from ShellScriptPartHandler: [['text/x-shellscript']]
2021-08-15 16:56:30,467 - stages.py[DEBUG]: Added default handler for {'text/cloud-boothook'} from BootHookPartHandler: [['text/cloud-boothook']]
2021-08-15 16:56:30,467 - stages.py[DEBUG]: Added default handler for {'text/upstart-job'} from UpstartJobPartHandler: [['text/upstart-job']]
2021-08-15 16:56:30,467 - stages.py[DEBUG]: Added default handler for {'text/jinja2'} from JinjaTemplatePartHandler: [['text/jinja2']]
2021-08-15 16:56:30,467 - __init__.py[DEBUG]: Calling handler CloudConfigPartHandler: [['text/cloud-config', 'text/cloud-config-jsonp']] (__begin__, None, 3) with frequency once-per-instance
2021-08-15 16:56:30,467 - __init__.py[DEBUG]: Calling handler ShellScriptPartHandler: [['text/x-shellscript']] (__begin__, None, 2) with frequency once-per-instance
2021-08-15 16:56:30,468 - __init__.py[DEBUG]: Calling handler BootHookPartHandler: [['text/cloud-boothook']] (__begin__, None, 2) with frequency once-per-instance
2021-08-15 16:56:30,468 - __init__.py[DEBUG]: Calling handler UpstartJobPartHandler: [['text/upstart-job']] (__begin__, None, 2) with frequency once-per-instance
2021-08-15 16:56:30,468 - __init__.py[DEBUG]: Calling handler JinjaTemplatePartHandler: [['text/jinja2']] (__begin__, None, 3) with frequency once-per-instance
2021-08-15 16:56:30,468 - __init__.py[DEBUG]: {'MIME-Version': '1.0', 'Content-Type': 'text/cloud-config', 'Content-Disposition': 'attachment; filename="part-001"'}
2021-08-15 16:56:30,468 - __init__.py[DEBUG]: Calling handler CloudConfigPartHandler: [['text/cloud-config', 'text/cloud-config-jsonp']] (text/cloud-config, part-001, 3) with frequency once-per-instance
2021-08-15 16:56:30,468 - util.py[DEBUG]: Attempting to load yaml from string of length 363 with allowed root types (<class 'dict'>,)
2021-08-15 16:56:30,470 - cloud_config.py[DEBUG]: Merging by applying [('dict', ['replace']), ('list', []), ('str', [])]
2021-08-15 16:56:30,470 - __init__.py[DEBUG]: Calling handler CloudConfigPartHandler: [['text/cloud-config', 'text/cloud-config-jsonp']] (__end__, None, 3) with frequency once-per-instance
2021-08-15 16:56:30,471 - util.py[DEBUG]: Writing to /var/lib/cloud/instances/iid-datasource-none/cloud-config.txt - wb: [600] 442 bytes
2021-08-15 16:56:30,471 - __init__.py[DEBUG]: Calling handler ShellScriptPartHandler: [['text/x-shellscript']] (__end__, None, 2) with frequency once-per-instance
2021-08-15 16:56:30,471 - __init__.py[DEBUG]: Calling handler BootHookPartHandler: [['text/cloud-boothook']] (__end__, None, 2) with frequency once-per-instance
2021-08-15 16:56:30,471 - __init__.py[DEBUG]: Calling handler UpstartJobPartHandler: [['text/upstart-job']] (__end__, None, 2) with frequency once-per-instance
2021-08-15 16:56:30,471 - __init__.py[DEBUG]: Calling handler JinjaTemplatePartHandler: [['text/jinja2']] (__end__, None, 3) with frequency once-per-instance
2021-08-15 16:56:30,472 - handlers.py[DEBUG]: finish: init-network/consume-user-data: SUCCESS: reading and applying user-data
2021-08-15 16:56:30,472 - handlers.py[DEBUG]: start: init-network/consume-vendor-data: reading and applying vendor-data
2021-08-15 16:56:30,472 - stages.py[DEBUG]: no vendordata from datasource
2021-08-15 16:56:30,472 - handlers.py[DEBUG]: finish: init-network/consume-vendor-data: SUCCESS: reading and applying vendor-data
2021-08-15 16:56:30,472 - util.py[DEBUG]: Reading from /etc/cloud/cloud.cfg (quiet=False)
2021-08-15 16:56:30,472 - util.py[DEBUG]: Read 3517 bytes from /etc/cloud/cloud.cfg
2021-08-15 16:56:30,472 - util.py[DEBUG]: Attempting to load yaml from string of length 3517 with allowed root types (<class 'dict'>,)
2021-08-15 16:56:30,481 - util.py[DEBUG]: Reading from /etc/cloud/cloud.cfg.d/subiquity-disable-cloudinit-networking.cfg (quiet=False)
2021-08-15 16:56:30,481 - util.py[DEBUG]: Read 28 bytes from /etc/cloud/cloud.cfg.d/subiquity-disable-cloudinit-networking.cfg
2021-08-15 16:56:30,481 - util.py[DEBUG]: Attempting to load yaml from string of length 28 with allowed root types (<class 'dict'>,)
2021-08-15 16:56:30,481 - util.py[DEBUG]: Reading from /etc/cloud/cloud.cfg.d/curtin-preserve-sources.cfg (quiet=False)
2021-08-15 16:56:30,481 - util.py[DEBUG]: Read 35 bytes from /etc/cloud/cloud.cfg.d/curtin-preserve-sources.cfg
2021-08-15 16:56:30,481 - util.py[DEBUG]: Attempting to load yaml from string of length 35 with allowed root types (<class 'dict'>,)
2021-08-15 16:56:30,482 - util.py[DEBUG]: Reading from /etc/cloud/cloud.cfg.d/99-installer.cfg (quiet=False)
2021-08-15 16:56:30,482 - util.py[DEBUG]: Read 543 bytes from /etc/cloud/cloud.cfg.d/99-installer.cfg
2021-08-15 16:56:30,482 - util.py[DEBUG]: Attempting to load yaml from string of length 543 with allowed root types (<class 'dict'>,)
2021-08-15 16:56:30,483 - util.py[DEBUG]: Reading from /etc/cloud/cloud.cfg.d/90_dpkg.cfg (quiet=False)
2021-08-15 16:56:30,483 - util.py[DEBUG]: Read 277 bytes from /etc/cloud/cloud.cfg.d/90_dpkg.cfg
2021-08-15 16:56:30,483 - util.py[DEBUG]: Attempting to load yaml from string of length 277 with allowed root types (<class 'dict'>,)
2021-08-15 16:56:30,484 - util.py[DEBUG]: Reading from /etc/cloud/cloud.cfg.d/05_logging.cfg (quiet=False)
2021-08-15 16:56:30,484 - util.py[DEBUG]: Read 2057 bytes from /etc/cloud/cloud.cfg.d/05_logging.cfg
2021-08-15 16:56:30,484 - util.py[DEBUG]: Attempting to load yaml from string of length 2057 with allowed root types (<class 'dict'>,)
2021-08-15 16:56:30,487 - util.py[DEBUG]: Reading from /run/cloud-init/cloud.cfg (quiet=False)
2021-08-15 16:56:30,487 - util.py[DEBUG]: Attempting to load yaml from string of length 0 with allowed root types (<class 'dict'>,)
2021-08-15 16:56:30,487 - util.py[DEBUG]: loaded blob returned None, returning default.
2021-08-15 16:56:30,487 - util.py[DEBUG]: Reading from /var/lib/cloud/instance/cloud-config.txt (quiet=False)
2021-08-15 16:56:30,487 - util.py[DEBUG]: Read 442 bytes from /var/lib/cloud/instance/cloud-config.txt
2021-08-15 16:56:30,487 - util.py[DEBUG]: Attempting to load yaml from string of length 442 with allowed root types (<class 'dict'>,)
2021-08-15 16:56:30,490 - util.py[DEBUG]: Reading from /var/lib/cloud/instance/cloud-config.txt (quiet=False)
2021-08-15 16:56:30,490 - util.py[DEBUG]: Read 442 bytes from /var/lib/cloud/instance/cloud-config.txt
2021-08-15 16:56:30,490 - util.py[DEBUG]: Attempting to load yaml from string of length 442 with allowed root types (<class 'dict'>,)
2021-08-15 16:56:30,499 - handlers.py[DEBUG]: start: init-network/activate-datasource: activating datasource
2021-08-15 16:56:30,500 - util.py[DEBUG]: Writing to /var/lib/cloud/instance/obj.pkl - wb: [400] 9181 bytes
2021-08-15 16:56:30,501 - handlers.py[DEBUG]: finish: init-network/activate-datasource: SUCCESS: activating datasource
2021-08-15 16:56:30,502 - main.py[DEBUG]: no di_report found in config.
2021-08-15 16:56:30,528 - stages.py[DEBUG]: Using distro class <class 'cloudinit.distros.ubuntu.Distro'>
2021-08-15 16:56:30,529 - stages.py[DEBUG]: Running module migrator (<module 'cloudinit.config.cc_migrator' from '/usr/lib/python3/dist-packages/cloudinit/config/cc_migrator.py'>) with frequency always
2021-08-15 16:56:30,529 - handlers.py[DEBUG]: start: init-network/config-migrator: running config-migrator with frequency always
2021-08-15 16:56:30,529 - helpers.py[DEBUG]: Running config-migrator using lock (<cloudinit.helpers.DummyLock object at 0x7feb6d3433c8>)
2021-08-15 16:56:30,529 - cc_migrator.py[DEBUG]: Migrated 0 semaphore files to there canonicalized names
2021-08-15 16:56:30,529 - handlers.py[DEBUG]: finish: init-network/config-migrator: SUCCESS: config-migrator ran successfully
2021-08-15 16:56:30,529 - stages.py[DEBUG]: Running module seed_random (<module 'cloudinit.config.cc_seed_random' from '/usr/lib/python3/dist-packages/cloudinit/config/cc_seed_random.py'>) with frequency once-per-instance
2021-08-15 16:56:30,530 - handlers.py[DEBUG]: start: init-network/config-seed_random: running config-seed_random with frequency once-per-instance
2021-08-15 16:56:30,530 - util.py[DEBUG]: Writing to /var/lib/cloud/instances/iid-datasource-none/sem/config_seed_random - wb: [644] 23 bytes
2021-08-15 16:56:30,530 - helpers.py[DEBUG]: Running config-seed_random using lock (<FileLock using file '/var/lib/cloud/instances/iid-datasource-none/sem/config_seed_random'>)
2021-08-15 16:56:30,530 - cc_seed_random.py[DEBUG]: no command provided
2021-08-15 16:56:30,530 - handlers.py[DEBUG]: finish: init-network/config-seed_random: SUCCESS: config-seed_random ran successfully
2021-08-15 16:56:30,530 - stages.py[DEBUG]: Running module bootcmd (<module 'cloudinit.config.cc_bootcmd' from '/usr/lib/python3/dist-packages/cloudinit/config/cc_bootcmd.py'>) with frequency always
2021-08-15 16:56:30,531 - handlers.py[DEBUG]: start: init-network/config-bootcmd: running config-bootcmd with frequency always
2021-08-15 16:56:30,531 - helpers.py[DEBUG]: Running config-bootcmd using lock (<cloudinit.helpers.DummyLock object at 0x7feb6d380cc0>)
2021-08-15 16:56:30,531 - cc_bootcmd.py[DEBUG]: Skipping module named bootcmd, no 'bootcmd' key in configuration
2021-08-15 16:56:30,531 - handlers.py[DEBUG]: finish: init-network/config-bootcmd: SUCCESS: config-bootcmd ran successfully
2021-08-15 16:56:30,531 - stages.py[DEBUG]: Running module write-files (<module 'cloudinit.config.cc_write_files' from '/usr/lib/python3/dist-packages/cloudinit/config/cc_write_files.py'>) with frequency once-per-instance
2021-08-15 16:56:30,531 - handlers.py[DEBUG]: start: init-network/config-write-files: running config-write-files with frequency once-per-instance
2021-08-15 16:56:30,531 - util.py[DEBUG]: Writing to /var/lib/cloud/instances/iid-datasource-none/sem/config_write_files - wb: [644] 24 bytes
2021-08-15 16:56:30,531 - helpers.py[DEBUG]: Running config-write-files using lock (<FileLock using file '/var/lib/cloud/instances/iid-datasource-none/sem/config_write_files'>)
2021-08-15 16:56:30,531 - cc_write_files.py[DEBUG]: Skipping module named write-files, no/empty 'write_files' key in configuration
2021-08-15 16:56:30,531 - handlers.py[DEBUG]: finish: init-network/config-write-files: SUCCESS: config-write-files ran successfully
2021-08-15 16:56:30,531 - stages.py[DEBUG]: Running module growpart (<module 'cloudinit.config.cc_growpart' from '/usr/lib/python3/dist-packages/cloudinit/config/cc_growpart.py'>) with frequency always
2021-08-15 16:56:30,532 - handlers.py[DEBUG]: start: init-network/config-growpart: running config-growpart with frequency always
2021-08-15 16:56:30,532 - helpers.py[DEBUG]: Running config-growpart using lock (<cloudinit.helpers.DummyLock object at 0x7feb6d336e10>)
2021-08-15 16:56:30,532 - cc_growpart.py[DEBUG]: growpart disabled: mode=off
2021-08-15 16:56:30,532 - handlers.py[DEBUG]: finish: init-network/config-growpart: SUCCESS: config-growpart ran successfully
2021-08-15 16:56:30,532 - stages.py[DEBUG]: Running module resizefs (<module 'cloudinit.config.cc_resizefs' from '/usr/lib/python3/dist-packages/cloudinit/config/cc_resizefs.py'>) with frequency always
2021-08-15 16:56:30,532 - handlers.py[DEBUG]: start: init-network/config-resizefs: running config-resizefs with frequency always
2021-08-15 16:56:30,532 - helpers.py[DEBUG]: Running config-resizefs using lock (<cloudinit.helpers.DummyLock object at 0x7feb6d336668>)
2021-08-15 16:56:30,551 - cc_resizefs.py[DEBUG]: Skipping module named resizefs, resizing disabled
2021-08-15 16:56:30,552 - handlers.py[DEBUG]: finish: init-network/config-resizefs: SUCCESS: config-resizefs ran successfully
2021-08-15 16:56:30,552 - stages.py[DEBUG]: Running module disk_setup (<module 'cloudinit.config.cc_disk_setup' from '/usr/lib/python3/dist-packages/cloudinit/config/cc_disk_setup.py'>) with frequency once-per-instance
2021-08-15 16:56:30,552 - handlers.py[DEBUG]: start: init-network/config-disk_setup: running config-disk_setup with frequency once-per-instance
2021-08-15 16:56:30,552 - util.py[DEBUG]: Writing to /var/lib/cloud/instances/iid-datasource-none/sem/config_disk_setup - wb: [644] 24 bytes
2021-08-15 16:56:30,552 - helpers.py[DEBUG]: Running config-disk_setup using lock (<FileLock using file '/var/lib/cloud/instances/iid-datasource-none/sem/config_disk_setup'>)
2021-08-15 16:56:30,553 - handlers.py[DEBUG]: finish: init-network/config-disk_setup: SUCCESS: config-disk_setup ran successfully
2021-08-15 16:56:30,553 - stages.py[DEBUG]: Running module mounts (<module 'cloudinit.config.cc_mounts' from '/usr/lib/python3/dist-packages/cloudinit/config/cc_mounts.py'>) with frequency once-per-instance
2021-08-15 16:56:30,553 - handlers.py[DEBUG]: start: init-network/config-mounts: running config-mounts with frequency once-per-instance
2021-08-15 16:56:30,553 - util.py[DEBUG]: Writing to /var/lib/cloud/instances/iid-datasource-none/sem/config_mounts - wb: [644] 23 bytes
2021-08-15 16:56:30,553 - helpers.py[DEBUG]: Running config-mounts using lock (<FileLock using file '/var/lib/cloud/instances/iid-datasource-none/sem/config_mounts'>)
2021-08-15 16:56:30,553 - cc_mounts.py[DEBUG]: mounts configuration is []
2021-08-15 16:56:30,553 - util.py[DEBUG]: Reading from /etc/fstab (quiet=False)
2021-08-15 16:56:30,553 - util.py[DEBUG]: Read 657 bytes from /etc/fstab
2021-08-15 16:56:30,554 - cc_mounts.py[DEBUG]: Attempting to determine the real name of ephemeral0
2021-08-15 16:56:30,554 - cc_mounts.py[DEBUG]: changed default device ephemeral0 => None
2021-08-15 16:56:30,554 - cc_mounts.py[DEBUG]: Ignoring nonexistent default named mount ephemeral0
2021-08-15 16:56:30,554 - cc_mounts.py[DEBUG]: Attempting to determine the real name of swap
2021-08-15 16:56:30,554 - cc_mounts.py[DEBUG]: changed default device swap => None
2021-08-15 16:56:30,554 - cc_mounts.py[DEBUG]: Ignoring nonexistent default named mount swap
2021-08-15 16:56:30,554 - cc_mounts.py[DEBUG]: no need to setup swap
2021-08-15 16:56:30,554 - cc_mounts.py[DEBUG]: No modifications to fstab needed
2021-08-15 16:56:30,554 - handlers.py[DEBUG]: finish: init-network/config-mounts: SUCCESS: config-mounts ran successfully
2021-08-15 16:56:30,554 - stages.py[DEBUG]: Running module set_hostname (<module 'cloudinit.config.cc_set_hostname' from '/usr/lib/python3/dist-packages/cloudinit/config/cc_set_hostname.py'>) with frequency once-per-instance
2021-08-15 16:56:30,554 - handlers.py[DEBUG]: start: init-network/config-set_hostname: running config-set_hostname with frequency once-per-instance
2021-08-15 16:56:30,554 - util.py[DEBUG]: Writing to /var/lib/cloud/instances/iid-datasource-none/sem/config_set_hostname - wb: [644] 24 bytes
2021-08-15 16:56:30,554 - helpers.py[DEBUG]: Running config-set_hostname using lock (<FileLock using file '/var/lib/cloud/instances/iid-datasource-none/sem/config_set_hostname'>)
2021-08-15 16:56:30,555 - cc_set_hostname.py[DEBUG]: Configuration option 'preserve_hostname' is set, not setting the hostname in module set_hostname
2021-08-15 16:56:30,555 - handlers.py[DEBUG]: finish: init-network/config-set_hostname: SUCCESS: config-set_hostname ran successfully
2021-08-15 16:56:30,555 - stages.py[DEBUG]: Running module update_hostname (<module 'cloudinit.config.cc_update_hostname' from '/usr/lib/python3/dist-packages/cloudinit/config/cc_update_hostname.py'>) with frequency always
2021-08-15 16:56:30,555 - handlers.py[DEBUG]: start: init-network/config-update_hostname: running config-update_hostname with frequency always
2021-08-15 16:56:30,555 - helpers.py[DEBUG]: Running config-update_hostname using lock (<cloudinit.helpers.DummyLock object at 0x7feb6d27c550>)
2021-08-15 16:56:30,555 - cc_update_hostname.py[DEBUG]: Configuration option 'preserve_hostname' is set, not updating the hostname in module update_hostname
2021-08-15 16:56:30,555 - handlers.py[DEBUG]: finish: init-network/config-update_hostname: SUCCESS: config-update_hostname ran successfully
2021-08-15 16:56:30,555 - stages.py[DEBUG]: Running module update_etc_hosts (<module 'cloudinit.config.cc_update_etc_hosts' from '/usr/lib/python3/dist-packages/cloudinit/config/cc_update_etc_hosts.py'>) with frequency always
2021-08-15 16:56:30,555 - handlers.py[DEBUG]: start: init-network/config-update_etc_hosts: running config-update_etc_hosts with frequency always
2021-08-15 16:56:30,555 - helpers.py[DEBUG]: Running config-update_etc_hosts using lock (<cloudinit.helpers.DummyLock object at 0x7feb6d27c240>)
2021-08-15 16:56:30,555 - cc_update_etc_hosts.py[DEBUG]: Configuration option 'manage_etc_hosts' is not set, not managing /etc/hosts in module update_etc_hosts
2021-08-15 16:56:30,555 - handlers.py[DEBUG]: finish: init-network/config-update_etc_hosts: SUCCESS: config-update_etc_hosts ran successfully
2021-08-15 16:56:30,555 - stages.py[DEBUG]: Running module ca-certs (<module 'cloudinit.config.cc_ca_certs' from '/usr/lib/python3/dist-packages/cloudinit/config/cc_ca_certs.py'>) with frequency once-per-instance
2021-08-15 16:56:30,555 - handlers.py[DEBUG]: start: init-network/config-ca-certs: running config-ca-certs with frequency once-per-instance
2021-08-15 16:56:30,556 - util.py[DEBUG]: Writing to /var/lib/cloud/instances/iid-datasource-none/sem/config_ca_certs - wb: [644] 24 bytes
2021-08-15 16:56:30,556 - helpers.py[DEBUG]: Running config-ca-certs using lock (<FileLock using file '/var/lib/cloud/instances/iid-datasource-none/sem/config_ca_certs'>)
2021-08-15 16:56:30,556 - cc_ca_certs.py[DEBUG]: Skipping module named ca-certs, no 'ca-certs' key in configuration
2021-08-15 16:56:30,556 - handlers.py[DEBUG]: finish: init-network/config-ca-certs: SUCCESS: config-ca-certs ran successfully
2021-08-15 16:56:30,556 - stages.py[DEBUG]: Running module rsyslog (<module 'cloudinit.config.cc_rsyslog' from '/usr/lib/python3/dist-packages/cloudinit/config/cc_rsyslog.py'>) with frequency once-per-instance
2021-08-15 16:56:30,556 - handlers.py[DEBUG]: start: init-network/config-rsyslog: running config-rsyslog with frequency once-per-instance
2021-08-15 16:56:30,556 - util.py[DEBUG]: Writing to /var/lib/cloud/instances/iid-datasource-none/sem/config_rsyslog - wb: [644] 24 bytes
2021-08-15 16:56:30,557 - helpers.py[DEBUG]: Running config-rsyslog using lock (<FileLock using file '/var/lib/cloud/instances/iid-datasource-none/sem/config_rsyslog'>)
2021-08-15 16:56:30,557 - cc_rsyslog.py[DEBUG]: Skipping module named rsyslog, no 'rsyslog' key in configuration
2021-08-15 16:56:30,557 - handlers.py[DEBUG]: finish: init-network/config-rsyslog: SUCCESS: config-rsyslog ran successfully
2021-08-15 16:56:30,557 - stages.py[DEBUG]: Running module users-groups (<module 'cloudinit.config.cc_users_groups' from '/usr/lib/python3/dist-packages/cloudinit/config/cc_users_groups.py'>) with frequency once-per-instance
2021-08-15 16:56:30,557 - handlers.py[DEBUG]: start: init-network/config-users-groups: running config-users-groups with frequency once-per-instance
2021-08-15 16:56:30,557 - util.py[DEBUG]: Writing to /var/lib/cloud/instances/iid-datasource-none/sem/config_users_groups - wb: [644] 23 bytes
2021-08-15 16:56:30,557 - helpers.py[DEBUG]: Running config-users-groups using lock (<FileLock using file '/var/lib/cloud/instances/iid-datasource-none/sem/config_users_groups'>)
2021-08-15 16:56:30,558 - util.py[DEBUG]: Reading from /etc/os-release (quiet=True)
2021-08-15 16:56:30,558 - util.py[DEBUG]: Read 386 bytes from /etc/os-release
2021-08-15 16:56:30,558 - util.py[DEBUG]: Reading from /etc/system-image/channel.ini (quiet=True)
2021-08-15 16:56:30,558 - util.py[DEBUG]: Read 0 bytes from /etc/system-image/channel.ini
2021-08-15 16:56:30,559 - __init__.py[DEBUG]: Adding user thales
2021-08-15 16:56:30,559 - util.py[DEBUG]: Running hidden command to protect sensitive input/output logstring: ['useradd', 'thales', '--comment', 'thales', '--groups', 'adm,cdrom,dip,plugdev,lxd,sudo', '--password', 'REDACTED', '--shell', '/bin/bash', '-m']
2021-08-15 16:56:30,707 - handlers.py[DEBUG]: finish: init-network/config-users-groups: SUCCESS: config-users-groups ran successfully
2021-08-15 16:56:30,707 - stages.py[DEBUG]: Running module ssh (<module 'cloudinit.config.cc_ssh' from '/usr/lib/python3/dist-packages/cloudinit/config/cc_ssh.py'>) with frequency once-per-instance
2021-08-15 16:56:30,708 - handlers.py[DEBUG]: start: init-network/config-ssh: running config-ssh with frequency once-per-instance
2021-08-15 16:56:30,708 - util.py[DEBUG]: Writing to /var/lib/cloud/instances/iid-datasource-none/sem/config_ssh - wb: [644] 24 bytes
2021-08-15 16:56:30,708 - helpers.py[DEBUG]: Running config-ssh using lock (<FileLock using file '/var/lib/cloud/instances/iid-datasource-none/sem/config_ssh'>)
2021-08-15 16:56:30,709 - util.py[DEBUG]: Attempting to remove /etc/ssh/ssh_host_ed25519_key
2021-08-15 16:56:30,709 - util.py[DEBUG]: Attempting to remove /etc/ssh/ssh_host_ed25519_key.pub
2021-08-15 16:56:30,709 - util.py[DEBUG]: Attempting to remove /etc/ssh/ssh_host_ecdsa_key
2021-08-15 16:56:30,710 - util.py[DEBUG]: Attempting to remove /etc/ssh/ssh_host_rsa_key.pub
2021-08-15 16:56:30,710 - util.py[DEBUG]: Attempting to remove /etc/ssh/ssh_host_rsa_key
2021-08-15 16:56:30,710 - util.py[DEBUG]: Attempting to remove /etc/ssh/ssh_host_ecdsa_key.pub
2021-08-15 16:56:30,710 - util.py[DEBUG]: Running command ['ssh-keygen', '-t', 'rsa', '-N', '', '-f', '/etc/ssh/ssh_host_rsa_key'] with allowed return codes [0] (shell=False, capture=True)
2021-08-15 16:56:30,788 - util.py[DEBUG]: Running command ['ssh-keygen', '-t', 'dsa', '-N', '', '-f', '/etc/ssh/ssh_host_dsa_key'] with allowed return codes [0] (shell=False, capture=True)
2021-08-15 16:56:30,906 - util.py[DEBUG]: Running command ['ssh-keygen', '-t', 'ecdsa', '-N', '', '-f', '/etc/ssh/ssh_host_ecdsa_key'] with allowed return codes [0] (shell=False, capture=True)
2021-08-15 16:56:30,913 - util.py[DEBUG]: Running command ['ssh-keygen', '-t', 'ed25519', '-N', '', '-f', '/etc/ssh/ssh_host_ed25519_key'] with allowed return codes [0] (shell=False, capture=True)
2021-08-15 16:56:30,918 - util.py[DEBUG]: Reading from /etc/ssh/ssh_host_ed25519_key.pub (quiet=False)
2021-08-15 16:56:30,918 - util.py[DEBUG]: Read 94 bytes from /etc/ssh/ssh_host_ed25519_key.pub
2021-08-15 16:56:30,918 - util.py[DEBUG]: Reading from /etc/ssh/ssh_host_rsa_key.pub (quiet=False)
2021-08-15 16:56:30,918 - util.py[DEBUG]: Read 394 bytes from /etc/ssh/ssh_host_rsa_key.pub
2021-08-15 16:56:30,918 - util.py[DEBUG]: Reading from /etc/ssh/ssh_host_ecdsa_key.pub (quiet=False)
2021-08-15 16:56:30,918 - util.py[DEBUG]: Read 174 bytes from /etc/ssh/ssh_host_ecdsa_key.pub
2021-08-15 16:56:30,919 - util.py[DEBUG]: Changing the ownership of /root/.ssh to 0:0
2021-08-15 16:56:30,919 - util.py[DEBUG]: Reading from /etc/ssh/sshd_config (quiet=False)
2021-08-15 16:56:30,920 - util.py[DEBUG]: Read 3264 bytes from /etc/ssh/sshd_config
2021-08-15 16:56:30,921 - util.py[DEBUG]: Writing to /root/.ssh/authorized_keys - wb: [600] 0 bytes
2021-08-15 16:56:30,921 - util.py[DEBUG]: Changing the ownership of /root/.ssh/authorized_keys to 0:0
2021-08-15 16:56:30,921 - handlers.py[DEBUG]: finish: init-network/config-ssh: SUCCESS: config-ssh ran successfully
2021-08-15 16:56:30,921 - main.py[DEBUG]: Ran 15 modules with 0 failures
2021-08-15 16:56:30,922 - atomic_helper.py[DEBUG]: Atomically writing to file /var/lib/cloud/data/status.json (via temporary file /var/lib/cloud/data/tmpo58gfz2a) - w: [644] 512 bytes/chars
2021-08-15 16:56:30,922 - util.py[DEBUG]: Reading from /proc/uptime (quiet=False)
2021-08-15 16:56:30,922 - util.py[DEBUG]: Read 11 bytes from /proc/uptime
2021-08-15 16:56:30,922 - util.py[DEBUG]: cloud-init mode 'init' took 0.580 seconds (0.58)
2021-08-15 16:56:30,922 - handlers.py[DEBUG]: finish: init-network: SUCCESS: searching for network datasources
2021-08-15 16:56:36,951 - util.py[DEBUG]: Cloud-init v. 20.2-45-g5f7825e2-0ubuntu1~18.04.1 running 'modules:config' at Sun, 15 Aug 2021 16:56:36 +0000. Up 17.27 seconds.
2021-08-15 16:56:36,974 - stages.py[DEBUG]: Using distro class <class 'cloudinit.distros.ubuntu.Distro'>
2021-08-15 16:56:36,975 - stages.py[DEBUG]: Running module emit_upstart (<module 'cloudinit.config.cc_emit_upstart' from '/usr/lib/python3/dist-packages/cloudinit/config/cc_emit_upstart.py'>) with frequency always
2021-08-15 16:56:36,975 - handlers.py[DEBUG]: start: modules-config/config-emit_upstart: running config-emit_upstart with frequency always
2021-08-15 16:56:36,975 - helpers.py[DEBUG]: Running config-emit_upstart using lock (<cloudinit.helpers.DummyLock object at 0x7f81db6792e8>)
2021-08-15 16:56:36,975 - cc_emit_upstart.py[DEBUG]: no /sbin/initctl located
2021-08-15 16:56:36,975 - cc_emit_upstart.py[DEBUG]: not upstart system, 'emit_upstart' disabled
2021-08-15 16:56:36,975 - handlers.py[DEBUG]: finish: modules-config/config-emit_upstart: SUCCESS: config-emit_upstart ran successfully
2021-08-15 16:56:36,975 - stages.py[DEBUG]: Running module snap (<module 'cloudinit.config.cc_snap' from '/usr/lib/python3/dist-packages/cloudinit/config/cc_snap.py'>) with frequency once-per-instance
2021-08-15 16:56:36,975 - handlers.py[DEBUG]: start: modules-config/config-snap: running config-snap with frequency once-per-instance
2021-08-15 16:56:36,976 - util.py[DEBUG]: Writing to /var/lib/cloud/instances/iid-datasource-none/sem/config_snap - wb: [644] 23 bytes
2021-08-15 16:56:36,976 - helpers.py[DEBUG]: Running config-snap using lock (<FileLock using file '/var/lib/cloud/instances/iid-datasource-none/sem/config_snap'>)
2021-08-15 16:56:36,976 - cc_snap.py[DEBUG]: Skipping module named snap, no 'snap' key in configuration
2021-08-15 16:56:36,976 - handlers.py[DEBUG]: finish: modules-config/config-snap: SUCCESS: config-snap ran successfully
2021-08-15 16:56:36,976 - stages.py[DEBUG]: Running module ssh-import-id (<module 'cloudinit.config.cc_ssh_import_id' from '/usr/lib/python3/dist-packages/cloudinit/config/cc_ssh_import_id.py'>) with frequency once-per-instance
2021-08-15 16:56:36,976 - handlers.py[DEBUG]: start: modules-config/config-ssh-import-id: running config-ssh-import-id with frequency once-per-instance
2021-08-15 16:56:36,976 - util.py[DEBUG]: Writing to /var/lib/cloud/instances/iid-datasource-none/sem/config_ssh_import_id - wb: [644] 24 bytes
2021-08-15 16:56:36,977 - helpers.py[DEBUG]: Running config-ssh-import-id using lock (<FileLock using file '/var/lib/cloud/instances/iid-datasource-none/sem/config_ssh_import_id'>)
2021-08-15 16:56:36,977 - cc_ssh_import_id.py[DEBUG]: User thales is not configured for ssh_import_id
2021-08-15 16:56:36,977 - handlers.py[DEBUG]: finish: modules-config/config-ssh-import-id: SUCCESS: config-ssh-import-id ran successfully
2021-08-15 16:56:36,977 - stages.py[DEBUG]: Running module locale (<module 'cloudinit.config.cc_locale' from '/usr/lib/python3/dist-packages/cloudinit/config/cc_locale.py'>) with frequency once-per-instance
2021-08-15 16:56:36,977 - handlers.py[DEBUG]: start: modules-config/config-locale: running config-locale with frequency once-per-instance
2021-08-15 16:56:36,977 - util.py[DEBUG]: Writing to /var/lib/cloud/instances/iid-datasource-none/sem/config_locale - wb: [644] 25 bytes
2021-08-15 16:56:36,977 - helpers.py[DEBUG]: Running config-locale using lock (<FileLock using file '/var/lib/cloud/instances/iid-datasource-none/sem/config_locale'>)
2021-08-15 16:56:36,977 - util.py[DEBUG]: Reading from /etc/default/locale (quiet=False)
2021-08-15 16:56:36,977 - util.py[DEBUG]: Read 13 bytes from /etc/default/locale
2021-08-15 16:56:36,981 - cc_locale.py[DEBUG]: Setting locale to en_US.UTF-8
2021-08-15 16:56:36,981 - debian.py[DEBUG]: Generating locales for en_US.UTF-8
2021-08-15 16:56:36,981 - util.py[DEBUG]: Running command ['locale-gen', 'en_US.UTF-8'] with allowed return codes [0] (shell=False, capture=False)
2021-08-15 16:56:37,703 - debian.py[DEBUG]: Updating /etc/default/locale with locale setting LANG=en_US.UTF-8
2021-08-15 16:56:37,703 - util.py[DEBUG]: Running command ['update-locale', '--locale-file=/etc/default/locale', 'LANG=en_US.UTF-8'] with allowed return codes [0] (shell=False, capture=False)
2021-08-15 16:56:37,730 - handlers.py[DEBUG]: finish: modules-config/config-locale: SUCCESS: config-locale ran successfully
2021-08-15 16:56:37,730 - stages.py[DEBUG]: Running module set-passwords (<module 'cloudinit.config.cc_set_passwords' from '/usr/lib/python3/dist-packages/cloudinit/config/cc_set_passwords.py'>) with frequency once-per-instance
2021-08-15 16:56:37,731 - handlers.py[DEBUG]: start: modules-config/config-set-passwords: running config-set-passwords with frequency once-per-instance
2021-08-15 16:56:37,731 - util.py[DEBUG]: Writing to /var/lib/cloud/instances/iid-datasource-none/sem/config_set_passwords - wb: [644] 24 bytes
2021-08-15 16:56:37,731 - helpers.py[DEBUG]: Running config-set-passwords using lock (<FileLock using file '/var/lib/cloud/instances/iid-datasource-none/sem/config_set_passwords'>)
2021-08-15 16:56:37,731 - util.py[DEBUG]: Reading from /etc/ssh/sshd_config (quiet=False)
2021-08-15 16:56:37,731 - util.py[DEBUG]: Read 3264 bytes from /etc/ssh/sshd_config
2021-08-15 16:56:37,732 - ssh_util.py[DEBUG]: line 123: option PasswordAuthentication added with yes
2021-08-15 16:56:37,732 - util.py[DEBUG]: Writing to /etc/ssh/sshd_config - wb: [644] 3291 bytes
2021-08-15 16:56:37,732 - util.py[DEBUG]: Running command ['service', 'ssh', 'restart'] with allowed return codes [0] (shell=False, capture=True)
2021-08-15 16:56:37,775 - cc_set_passwords.py[DEBUG]: Restarted the SSH daemon.
2021-08-15 16:56:37,775 - handlers.py[DEBUG]: finish: modules-config/config-set-passwords: SUCCESS: config-set-passwords ran successfully
2021-08-15 16:56:37,775 - stages.py[DEBUG]: Running module grub-dpkg (<module 'cloudinit.config.cc_grub_dpkg' from '/usr/lib/python3/dist-packages/cloudinit/config/cc_grub_dpkg.py'>) with frequency once-per-instance
2021-08-15 16:56:37,776 - handlers.py[DEBUG]: start: modules-config/config-grub-dpkg: running config-grub-dpkg with frequency once-per-instance
2021-08-15 16:56:37,776 - util.py[DEBUG]: Writing to /var/lib/cloud/instances/iid-datasource-none/sem/config_grub_dpkg - wb: [644] 24 bytes
2021-08-15 16:56:37,776 - helpers.py[DEBUG]: Running config-grub-dpkg using lock (<FileLock using file '/var/lib/cloud/instances/iid-datasource-none/sem/config_grub_dpkg'>)
2021-08-15 16:56:37,776 - util.py[DEBUG]: Running command ['grub-probe', '-t', 'disk', '/boot'] with allowed return codes [0] (shell=False, capture=True)
2021-08-15 16:56:37,790 - util.py[DEBUG]: Running command ['udevadm', 'info', '--root', '--query=symlink', '/dev/sda'] with allowed return codes [0] (shell=False, capture=True)
2021-08-15 16:56:37,793 - cc_grub_dpkg.py[DEBUG]: considering these device symlinks: /dev/disk/by-id/ata-VBOX_HARDDISK_VBf24e065c-18e213b1,/dev/disk/by-path/pci-0000:00:0d.0-ata-1
2021-08-15 16:56:37,793 - cc_grub_dpkg.py[DEBUG]: filtered to these disk/by-id symlinks: /dev/disk/by-id/ata-VBOX_HARDDISK_VBf24e065c-18e213b1
2021-08-15 16:56:37,793 - cc_grub_dpkg.py[DEBUG]: selected /dev/disk/by-id/ata-VBOX_HARDDISK_VBf24e065c-18e213b1
2021-08-15 16:56:37,793 - cc_grub_dpkg.py[DEBUG]: Setting grub debconf-set-selections with '/dev/disk/by-id/ata-VBOX_HARDDISK_VBf24e065c-18e213b1','false'
2021-08-15 16:56:37,793 - util.py[DEBUG]: Running command ['debconf-set-selections'] with allowed return codes [0] (shell=False, capture=True)
2021-08-15 16:56:37,975 - handlers.py[DEBUG]: finish: modules-config/config-grub-dpkg: SUCCESS: config-grub-dpkg ran successfully
2021-08-15 16:56:37,975 - stages.py[DEBUG]: Running module apt-pipelining (<module 'cloudinit.config.cc_apt_pipelining' from '/usr/lib/python3/dist-packages/cloudinit/config/cc_apt_pipelining.py'>) with frequency once-per-instance
2021-08-15 16:56:37,975 - handlers.py[DEBUG]: start: modules-config/config-apt-pipelining: running config-apt-pipelining with frequency once-per-instance
2021-08-15 16:56:37,975 - util.py[DEBUG]: Writing to /var/lib/cloud/instances/iid-datasource-none/sem/config_apt_pipelining - wb: [644] 25 bytes
2021-08-15 16:56:37,976 - helpers.py[DEBUG]: Running config-apt-pipelining using lock (<FileLock using file '/var/lib/cloud/instances/iid-datasource-none/sem/config_apt_pipelining'>)
2021-08-15 16:56:37,976 - handlers.py[DEBUG]: finish: modules-config/config-apt-pipelining: SUCCESS: config-apt-pipelining ran successfully
2021-08-15 16:56:37,976 - stages.py[DEBUG]: Running module apt-configure (<module 'cloudinit.config.cc_apt_configure' from '/usr/lib/python3/dist-packages/cloudinit/config/cc_apt_configure.py'>) with frequency once-per-instance
2021-08-15 16:56:37,976 - handlers.py[DEBUG]: start: modules-config/config-apt-configure: running config-apt-configure with frequency once-per-instance
2021-08-15 16:56:37,976 - util.py[DEBUG]: Writing to /var/lib/cloud/instances/iid-datasource-none/sem/config_apt_configure - wb: [644] 25 bytes
2021-08-15 16:56:37,977 - helpers.py[DEBUG]: Running config-apt-configure using lock (<FileLock using file '/var/lib/cloud/instances/iid-datasource-none/sem/config_apt_configure'>)
2021-08-15 16:56:37,977 - cc_apt_configure.py[DEBUG]: debconf_selections was not set in config
2021-08-15 16:56:37,977 - cc_apt_configure.py[DEBUG]: handling apt config: {'preserve_sources_list': True}
2021-08-15 16:56:37,977 - util.py[DEBUG]: Running command ['lsb_release', '--all'] with allowed return codes [0] (shell=False, capture=True)
2021-08-15 16:56:38,030 - util.py[DEBUG]: Running command ['dpkg', '--print-architecture'] with allowed return codes [0] (shell=False, capture=True)
2021-08-15 16:56:38,033 - cc_apt_configure.py[DEBUG]: got primary mirror: None
2021-08-15 16:56:38,034 - cc_apt_configure.py[DEBUG]: got security mirror: None
2021-08-15 16:56:38,034 - util.py[DEBUG]: Running command ['dpkg', '--print-architecture'] with allowed return codes [0] (shell=False, capture=True)
2021-08-15 16:56:38,037 - util.py[DEBUG]: search for mirror in candidates: '[]'
2021-08-15 16:56:38,038 - util.py[DEBUG]: search for mirror in candidates: '[]'
2021-08-15 16:56:38,038 - __init__.py[DEBUG]: filtered distro mirror info: {'primary': 'http://archive.ubuntu.com/ubuntu', 'security': 'http://security.ubuntu.com/ubuntu'}
2021-08-15 16:56:38,038 - cc_apt_configure.py[DEBUG]: Apt Mirror info: {'primary': 'http://archive.ubuntu.com/ubuntu', 'security': 'http://security.ubuntu.com/ubuntu', 'PRIMARY': 'http://archive.ubuntu.com/ubuntu', 'SECURITY': 'http://security.ubuntu.com/ubuntu', 'MIRROR': 'http://archive.ubuntu.com/ubuntu'}
2021-08-15 16:56:38,038 - handlers.py[DEBUG]: finish: modules-config/config-apt-configure: SUCCESS: config-apt-configure ran successfully
2021-08-15 16:56:38,038 - stages.py[DEBUG]: Running module ubuntu-advantage (<module 'cloudinit.config.cc_ubuntu_advantage' from '/usr/lib/python3/dist-packages/cloudinit/config/cc_ubuntu_advantage.py'>) with frequency once-per-instance
2021-08-15 16:56:38,039 - handlers.py[DEBUG]: start: modules-config/config-ubuntu-advantage: running config-ubuntu-advantage with frequency once-per-instance
2021-08-15 16:56:38,039 - util.py[DEBUG]: Writing to /var/lib/cloud/instances/iid-datasource-none/sem/config_ubuntu_advantage - wb: [644] 25 bytes
2021-08-15 16:56:38,039 - helpers.py[DEBUG]: Running config-ubuntu-advantage using lock (<FileLock using file '/var/lib/cloud/instances/iid-datasource-none/sem/config_ubuntu_advantage'>)
2021-08-15 16:56:38,039 - cc_ubuntu_advantage.py[DEBUG]: Skipping module named ubuntu-advantage, no 'ubuntu-advantage' key in configuration
2021-08-15 16:56:38,039 - handlers.py[DEBUG]: finish: modules-config/config-ubuntu-advantage: SUCCESS: config-ubuntu-advantage ran successfully
2021-08-15 16:56:38,039 - stages.py[DEBUG]: Running module ntp (<module 'cloudinit.config.cc_ntp' from '/usr/lib/python3/dist-packages/cloudinit/config/cc_ntp.py'>) with frequency once-per-instance
2021-08-15 16:56:38,039 - handlers.py[DEBUG]: start: modules-config/config-ntp: running config-ntp with frequency once-per-instance
2021-08-15 16:56:38,040 - util.py[DEBUG]: Writing to /var/lib/cloud/instances/iid-datasource-none/sem/config_ntp - wb: [644] 25 bytes
2021-08-15 16:56:38,040 - helpers.py[DEBUG]: Running config-ntp using lock (<FileLock using file '/var/lib/cloud/instances/iid-datasource-none/sem/config_ntp'>)
2021-08-15 16:56:38,040 - cc_ntp.py[DEBUG]: Skipping module named ntp, not present or disabled by cfg
2021-08-15 16:56:38,040 - handlers.py[DEBUG]: finish: modules-config/config-ntp: SUCCESS: config-ntp ran successfully
2021-08-15 16:56:38,040 - stages.py[DEBUG]: Running module timezone (<module 'cloudinit.config.cc_timezone' from '/usr/lib/python3/dist-packages/cloudinit/config/cc_timezone.py'>) with frequency once-per-instance
2021-08-15 16:56:38,040 - handlers.py[DEBUG]: start: modules-config/config-timezone: running config-timezone with frequency once-per-instance
2021-08-15 16:56:38,040 - util.py[DEBUG]: Writing to /var/lib/cloud/instances/iid-datasource-none/sem/config_timezone - wb: [644] 25 bytes
2021-08-15 16:56:38,040 - helpers.py[DEBUG]: Running config-timezone using lock (<FileLock using file '/var/lib/cloud/instances/iid-datasource-none/sem/config_timezone'>)
2021-08-15 16:56:38,041 - cc_timezone.py[DEBUG]: Skipping module named timezone, no 'timezone' specified
2021-08-15 16:56:38,041 - handlers.py[DEBUG]: finish: modules-config/config-timezone: SUCCESS: config-timezone ran successfully
2021-08-15 16:56:38,041 - stages.py[DEBUG]: Running module disable-ec2-metadata (<module 'cloudinit.config.cc_disable_ec2_metadata' from '/usr/lib/python3/dist-packages/cloudinit/config/cc_disable_ec2_metadata.py'>) with frequency always
2021-08-15 16:56:38,041 - handlers.py[DEBUG]: start: modules-config/config-disable-ec2-metadata: running config-disable-ec2-metadata with frequency always
2021-08-15 16:56:38,041 - helpers.py[DEBUG]: Running config-disable-ec2-metadata using lock (<cloudinit.helpers.DummyLock object at 0x7f81db5ffe48>)
2021-08-15 16:56:38,041 - cc_disable_ec2_metadata.py[DEBUG]: Skipping module named disable-ec2-metadata, disabling the ec2 route not enabled
2021-08-15 16:56:38,041 - handlers.py[DEBUG]: finish: modules-config/config-disable-ec2-metadata: SUCCESS: config-disable-ec2-metadata ran successfully
2021-08-15 16:56:38,041 - stages.py[DEBUG]: Running module runcmd (<module 'cloudinit.config.cc_runcmd' from '/usr/lib/python3/dist-packages/cloudinit/config/cc_runcmd.py'>) with frequency once-per-instance
2021-08-15 16:56:38,041 - handlers.py[DEBUG]: start: modules-config/config-runcmd: running config-runcmd with frequency once-per-instance
2021-08-15 16:56:38,041 - util.py[DEBUG]: Writing to /var/lib/cloud/instances/iid-datasource-none/sem/config_runcmd - wb: [644] 24 bytes
2021-08-15 16:56:38,041 - helpers.py[DEBUG]: Running config-runcmd using lock (<FileLock using file '/var/lib/cloud/instances/iid-datasource-none/sem/config_runcmd'>)
2021-08-15 16:56:38,042 - cc_runcmd.py[DEBUG]: Skipping module named runcmd, no 'runcmd' key in configuration
2021-08-15 16:56:38,042 - handlers.py[DEBUG]: finish: modules-config/config-runcmd: SUCCESS: config-runcmd ran successfully
2021-08-15 16:56:38,042 - stages.py[DEBUG]: Running module byobu (<module 'cloudinit.config.cc_byobu' from '/usr/lib/python3/dist-packages/cloudinit/config/cc_byobu.py'>) with frequency once-per-instance
2021-08-15 16:56:38,042 - handlers.py[DEBUG]: start: modules-config/config-byobu: running config-byobu with frequency once-per-instance
2021-08-15 16:56:38,042 - util.py[DEBUG]: Writing to /var/lib/cloud/instances/iid-datasource-none/sem/config_byobu - wb: [644] 24 bytes
2021-08-15 16:56:38,042 - helpers.py[DEBUG]: Running config-byobu using lock (<FileLock using file '/var/lib/cloud/instances/iid-datasource-none/sem/config_byobu'>)
2021-08-15 16:56:38,042 - cc_byobu.py[DEBUG]: Skipping module named byobu, no 'byobu' values found
2021-08-15 16:56:38,042 - handlers.py[DEBUG]: finish: modules-config/config-byobu: SUCCESS: config-byobu ran successfully
2021-08-15 16:56:38,042 - main.py[DEBUG]: Ran 14 modules with 0 failures
2021-08-15 16:56:38,043 - atomic_helper.py[DEBUG]: Atomically writing to file /var/lib/cloud/data/status.json (via temporary file /var/lib/cloud/data/tmpsnst3rhz) - w: [644] 540 bytes/chars
2021-08-15 16:56:38,043 - util.py[DEBUG]: Reading from /proc/uptime (quiet=False)
2021-08-15 16:56:38,043 - util.py[DEBUG]: Read 11 bytes from /proc/uptime
2021-08-15 16:56:38,043 - util.py[DEBUG]: cloud-init mode 'modules' took 1.163 seconds (1.16)
2021-08-15 16:56:38,043 - handlers.py[DEBUG]: finish: modules-config: SUCCESS: running modules for config
2021-08-15 16:56:38,481 - util.py[DEBUG]: Cloud-init v. 20.2-45-g5f7825e2-0ubuntu1~18.04.1 running 'modules:final' at Sun, 15 Aug 2021 16:56:38 +0000. Up 18.80 seconds.
2021-08-15 16:56:38,513 - stages.py[DEBUG]: Using distro class <class 'cloudinit.distros.ubuntu.Distro'>
2021-08-15 16:56:38,514 - stages.py[DEBUG]: Running module package-update-upgrade-install (<module 'cloudinit.config.cc_package_update_upgrade_install' from '/usr/lib/python3/dist-packages/cloudinit/config/cc_package_update_upgrade_install.py'>) with frequency once-per-instance
2021-08-15 16:56:38,514 - handlers.py[DEBUG]: start: modules-final/config-package-update-upgrade-install: running config-package-update-upgrade-install with frequency once-per-instance
2021-08-15 16:56:38,515 - util.py[DEBUG]: Writing to /var/lib/cloud/instances/iid-datasource-none/sem/config_package_update_upgrade_install - wb: [644] 25 bytes
2021-08-15 16:56:38,515 - helpers.py[DEBUG]: Running config-package-update-upgrade-install using lock (<FileLock using file '/var/lib/cloud/instances/iid-datasource-none/sem/config_package_update_upgrade_install'>)
2021-08-15 16:56:38,515 - handlers.py[DEBUG]: finish: modules-final/config-package-update-upgrade-install: SUCCESS: config-package-update-upgrade-install ran successfully
2021-08-15 16:56:38,515 - stages.py[DEBUG]: Running module fan (<module 'cloudinit.config.cc_fan' from '/usr/lib/python3/dist-packages/cloudinit/config/cc_fan.py'>) with frequency once-per-instance
2021-08-15 16:56:38,515 - handlers.py[DEBUG]: start: modules-final/config-fan: running config-fan with frequency once-per-instance
2021-08-15 16:56:38,515 - util.py[DEBUG]: Writing to /var/lib/cloud/instances/iid-datasource-none/sem/config_fan - wb: [644] 24 bytes
2021-08-15 16:56:38,516 - helpers.py[DEBUG]: Running config-fan using lock (<FileLock using file '/var/lib/cloud/instances/iid-datasource-none/sem/config_fan'>)
2021-08-15 16:56:38,516 - cc_fan.py[DEBUG]: fan: no 'fan' config entry. disabling
2021-08-15 16:56:38,516 - handlers.py[DEBUG]: finish: modules-final/config-fan: SUCCESS: config-fan ran successfully
2021-08-15 16:56:38,516 - stages.py[DEBUG]: Running module landscape (<module 'cloudinit.config.cc_landscape' from '/usr/lib/python3/dist-packages/cloudinit/config/cc_landscape.py'>) with frequency once-per-instance
2021-08-15 16:56:38,516 - handlers.py[DEBUG]: start: modules-final/config-landscape: running config-landscape with frequency once-per-instance
2021-08-15 16:56:38,516 - util.py[DEBUG]: Writing to /var/lib/cloud/instances/iid-datasource-none/sem/config_landscape - wb: [644] 25 bytes
2021-08-15 16:56:38,516 - helpers.py[DEBUG]: Running config-landscape using lock (<FileLock using file '/var/lib/cloud/instances/iid-datasource-none/sem/config_landscape'>)
2021-08-15 16:56:38,516 - handlers.py[DEBUG]: finish: modules-final/config-landscape: SUCCESS: config-landscape ran successfully
2021-08-15 16:56:38,516 - stages.py[DEBUG]: Running module lxd (<module 'cloudinit.config.cc_lxd' from '/usr/lib/python3/dist-packages/cloudinit/config/cc_lxd.py'>) with frequency once-per-instance
2021-08-15 16:56:38,517 - handlers.py[DEBUG]: start: modules-final/config-lxd: running config-lxd with frequency once-per-instance
2021-08-15 16:56:38,517 - util.py[DEBUG]: Writing to /var/lib/cloud/instances/iid-datasource-none/sem/config_lxd - wb: [644] 25 bytes
2021-08-15 16:56:38,517 - helpers.py[DEBUG]: Running config-lxd using lock (<FileLock using file '/var/lib/cloud/instances/iid-datasource-none/sem/config_lxd'>)
2021-08-15 16:56:38,517 - cc_lxd.py[DEBUG]: Skipping module named lxd, not present or disabled by cfg
2021-08-15 16:56:38,517 - handlers.py[DEBUG]: finish: modules-final/config-lxd: SUCCESS: config-lxd ran successfully
2021-08-15 16:56:38,517 - stages.py[DEBUG]: Running module ubuntu-drivers (<module 'cloudinit.config.cc_ubuntu_drivers' from '/usr/lib/python3/dist-packages/cloudinit/config/cc_ubuntu_drivers.py'>) with frequency once-per-instance
2021-08-15 16:56:38,517 - handlers.py[DEBUG]: start: modules-final/config-ubuntu-drivers: running config-ubuntu-drivers with frequency once-per-instance
2021-08-15 16:56:38,517 - util.py[DEBUG]: Writing to /var/lib/cloud/instances/iid-datasource-none/sem/config_ubuntu_drivers - wb: [644] 25 bytes
2021-08-15 16:56:38,518 - helpers.py[DEBUG]: Running config-ubuntu-drivers using lock (<FileLock using file '/var/lib/cloud/instances/iid-datasource-none/sem/config_ubuntu_drivers'>)
2021-08-15 16:56:38,518 - cc_ubuntu_drivers.py[DEBUG]: Skipping module named ubuntu-drivers, no 'drivers' key in config
2021-08-15 16:56:38,518 - handlers.py[DEBUG]: finish: modules-final/config-ubuntu-drivers: SUCCESS: config-ubuntu-drivers ran successfully
2021-08-15 16:56:38,518 - stages.py[DEBUG]: Running module puppet (<module 'cloudinit.config.cc_puppet' from '/usr/lib/python3/dist-packages/cloudinit/config/cc_puppet.py'>) with frequency once-per-instance
2021-08-15 16:56:38,518 - handlers.py[DEBUG]: start: modules-final/config-puppet: running config-puppet with frequency once-per-instance
2021-08-15 16:56:38,518 - util.py[DEBUG]: Writing to /var/lib/cloud/instances/iid-datasource-none/sem/config_puppet - wb: [644] 25 bytes
2021-08-15 16:56:38,518 - helpers.py[DEBUG]: Running config-puppet using lock (<FileLock using file '/var/lib/cloud/instances/iid-datasource-none/sem/config_puppet'>)
2021-08-15 16:56:38,518 - cc_puppet.py[DEBUG]: Skipping module named puppet, no 'puppet' configuration found
2021-08-15 16:56:38,518 - handlers.py[DEBUG]: finish: modules-final/config-puppet: SUCCESS: config-puppet ran successfully
2021-08-15 16:56:38,518 - stages.py[DEBUG]: Running module chef (<module 'cloudinit.config.cc_chef' from '/usr/lib/python3/dist-packages/cloudinit/config/cc_chef.py'>) with frequency once-per-instance
2021-08-15 16:56:38,519 - handlers.py[DEBUG]: start: modules-final/config-chef: running config-chef with frequency once-per-instance
2021-08-15 16:56:38,519 - util.py[DEBUG]: Writing to /var/lib/cloud/instances/iid-datasource-none/sem/config_chef - wb: [644] 25 bytes
2021-08-15 16:56:38,519 - helpers.py[DEBUG]: Running config-chef using lock (<FileLock using file '/var/lib/cloud/instances/iid-datasource-none/sem/config_chef'>)
2021-08-15 16:56:38,519 - cc_chef.py[DEBUG]: Skipping module named chef, no 'chef' key in configuration
2021-08-15 16:56:38,519 - handlers.py[DEBUG]: finish: modules-final/config-chef: SUCCESS: config-chef ran successfully
2021-08-15 16:56:38,519 - stages.py[DEBUG]: Running module mcollective (<module 'cloudinit.config.cc_mcollective' from '/usr/lib/python3/dist-packages/cloudinit/config/cc_mcollective.py'>) with frequency once-per-instance
2021-08-15 16:56:38,519 - handlers.py[DEBUG]: start: modules-final/config-mcollective: running config-mcollective with frequency once-per-instance
2021-08-15 16:56:38,519 - util.py[DEBUG]: Writing to /var/lib/cloud/instances/iid-datasource-none/sem/config_mcollective - wb: [644] 25 bytes
2021-08-15 16:56:38,520 - helpers.py[DEBUG]: Running config-mcollective using lock (<FileLock using file '/var/lib/cloud/instances/iid-datasource-none/sem/config_mcollective'>)
2021-08-15 16:56:38,520 - cc_mcollective.py[DEBUG]: Skipping module named mcollective, no 'mcollective' key in configuration
2021-08-15 16:56:38,520 - handlers.py[DEBUG]: finish: modules-final/config-mcollective: SUCCESS: config-mcollective ran successfully
2021-08-15 16:56:38,520 - stages.py[DEBUG]: Running module salt-minion (<module 'cloudinit.config.cc_salt_minion' from '/usr/lib/python3/dist-packages/cloudinit/config/cc_salt_minion.py'>) with frequency once-per-instance
2021-08-15 16:56:38,520 - handlers.py[DEBUG]: start: modules-final/config-salt-minion: running config-salt-minion with frequency once-per-instance
2021-08-15 16:56:38,520 - util.py[DEBUG]: Writing to /var/lib/cloud/instances/iid-datasource-none/sem/config_salt_minion - wb: [644] 25 bytes
2021-08-15 16:56:38,520 - helpers.py[DEBUG]: Running config-salt-minion using lock (<FileLock using file '/var/lib/cloud/instances/iid-datasource-none/sem/config_salt_minion'>)
2021-08-15 16:56:38,520 - cc_salt_minion.py[DEBUG]: Skipping module named salt-minion, no 'salt_minion' key in configuration
2021-08-15 16:56:38,520 - handlers.py[DEBUG]: finish: modules-final/config-salt-minion: SUCCESS: config-salt-minion ran successfully
2021-08-15 16:56:38,520 - stages.py[DEBUG]: Running module rightscale_userdata (<module 'cloudinit.config.cc_rightscale_userdata' from '/usr/lib/python3/dist-packages/cloudinit/config/cc_rightscale_userdata.py'>) with frequency once-per-instance
2021-08-15 16:56:38,521 - handlers.py[DEBUG]: start: modules-final/config-rightscale_userdata: running config-rightscale_userdata with frequency once-per-instance
2021-08-15 16:56:38,521 - util.py[DEBUG]: Writing to /var/lib/cloud/instances/iid-datasource-none/sem/config_rightscale_userdata - wb: [644] 25 bytes
2021-08-15 16:56:38,521 - helpers.py[DEBUG]: Running config-rightscale_userdata using lock (<FileLock using file '/var/lib/cloud/instances/iid-datasource-none/sem/config_rightscale_userdata'>)
2021-08-15 16:56:38,521 - cc_rightscale_userdata.py[DEBUG]: Failed to get raw userdata in module rightscale_userdata
2021-08-15 16:56:38,521 - handlers.py[DEBUG]: finish: modules-final/config-rightscale_userdata: SUCCESS: config-rightscale_userdata ran successfully
2021-08-15 16:56:38,521 - stages.py[DEBUG]: Running module scripts-vendor (<module 'cloudinit.config.cc_scripts_vendor' from '/usr/lib/python3/dist-packages/cloudinit/config/cc_scripts_vendor.py'>) with frequency once-per-instance
2021-08-15 16:56:38,521 - handlers.py[DEBUG]: start: modules-final/config-scripts-vendor: running config-scripts-vendor with frequency once-per-instance
2021-08-15 16:56:38,521 - util.py[DEBUG]: Writing to /var/lib/cloud/instances/iid-datasource-none/sem/config_scripts_vendor - wb: [644] 25 bytes
2021-08-15 16:56:38,522 - helpers.py[DEBUG]: Running config-scripts-vendor using lock (<FileLock using file '/var/lib/cloud/instances/iid-datasource-none/sem/config_scripts_vendor'>)
2021-08-15 16:56:38,522 - handlers.py[DEBUG]: finish: modules-final/config-scripts-vendor: SUCCESS: config-scripts-vendor ran successfully
2021-08-15 16:56:38,522 - stages.py[DEBUG]: Running module scripts-per-once (<module 'cloudinit.config.cc_scripts_per_once' from '/usr/lib/python3/dist-packages/cloudinit/config/cc_scripts_per_once.py'>) with frequency once
2021-08-15 16:56:38,522 - handlers.py[DEBUG]: start: modules-final/config-scripts-per-once: running config-scripts-per-once with frequency once
2021-08-15 16:56:38,522 - util.py[DEBUG]: Writing to /var/lib/cloud/sem/config_scripts_per_once.once - wb: [644] 25 bytes
2021-08-15 16:56:38,522 - helpers.py[DEBUG]: Running config-scripts-per-once using lock (<FileLock using file '/var/lib/cloud/sem/config_scripts_per_once.once'>)
2021-08-15 16:56:38,522 - handlers.py[DEBUG]: finish: modules-final/config-scripts-per-once: SUCCESS: config-scripts-per-once ran successfully
2021-08-15 16:56:38,522 - stages.py[DEBUG]: Running module scripts-per-boot (<module 'cloudinit.config.cc_scripts_per_boot' from '/usr/lib/python3/dist-packages/cloudinit/config/cc_scripts_per_boot.py'>) with frequency always
2021-08-15 16:56:38,523 - handlers.py[DEBUG]: start: modules-final/config-scripts-per-boot: running config-scripts-per-boot with frequency always
2021-08-15 16:56:38,523 - helpers.py[DEBUG]: Running config-scripts-per-boot using lock (<cloudinit.helpers.DummyLock object at 0x7eff59917fd0>)
2021-08-15 16:56:38,523 - handlers.py[DEBUG]: finish: modules-final/config-scripts-per-boot: SUCCESS: config-scripts-per-boot ran successfully
2021-08-15 16:56:38,523 - stages.py[DEBUG]: Running module scripts-per-instance (<module 'cloudinit.config.cc_scripts_per_instance' from '/usr/lib/python3/dist-packages/cloudinit/config/cc_scripts_per_instance.py'>) with frequency once-per-instance
2021-08-15 16:56:38,523 - handlers.py[DEBUG]: start: modules-final/config-scripts-per-instance: running config-scripts-per-instance with frequency once-per-instance
2021-08-15 16:56:38,523 - util.py[DEBUG]: Writing to /var/lib/cloud/instances/iid-datasource-none/sem/config_scripts_per_instance - wb: [644] 25 bytes
2021-08-15 16:56:38,523 - helpers.py[DEBUG]: Running config-scripts-per-instance using lock (<FileLock using file '/var/lib/cloud/instances/iid-datasource-none/sem/config_scripts_per_instance'>)
2021-08-15 16:56:38,523 - handlers.py[DEBUG]: finish: modules-final/config-scripts-per-instance: SUCCESS: config-scripts-per-instance ran successfully
2021-08-15 16:56:38,523 - stages.py[DEBUG]: Running module scripts-user (<module 'cloudinit.config.cc_scripts_user' from '/usr/lib/python3/dist-packages/cloudinit/config/cc_scripts_user.py'>) with frequency once-per-instance
2021-08-15 16:56:38,524 - handlers.py[DEBUG]: start: modules-final/config-scripts-user: running config-scripts-user with frequency once-per-instance
2021-08-15 16:56:38,524 - util.py[DEBUG]: Writing to /var/lib/cloud/instances/iid-datasource-none/sem/config_scripts_user - wb: [644] 24 bytes
2021-08-15 16:56:38,524 - helpers.py[DEBUG]: Running config-scripts-user using lock (<FileLock using file '/var/lib/cloud/instances/iid-datasource-none/sem/config_scripts_user'>)
2021-08-15 16:56:38,524 - handlers.py[DEBUG]: finish: modules-final/config-scripts-user: SUCCESS: config-scripts-user ran successfully
2021-08-15 16:56:38,524 - stages.py[DEBUG]: Running module ssh-authkey-fingerprints (<module 'cloudinit.config.cc_ssh_authkey_fingerprints' from '/usr/lib/python3/dist-packages/cloudinit/config/cc_ssh_authkey_fingerprints.py'>) with frequency once-per-instance
2021-08-15 16:56:38,524 - handlers.py[DEBUG]: start: modules-final/config-ssh-authkey-fingerprints: running config-ssh-authkey-fingerprints with frequency once-per-instance
2021-08-15 16:56:38,524 - util.py[DEBUG]: Writing to /var/lib/cloud/instances/iid-datasource-none/sem/config_ssh_authkey_fingerprints - wb: [644] 24 bytes
2021-08-15 16:56:38,525 - helpers.py[DEBUG]: Running config-ssh-authkey-fingerprints using lock (<FileLock using file '/var/lib/cloud/instances/iid-datasource-none/sem/config_ssh_authkey_fingerprints'>)
2021-08-15 16:56:38,525 - util.py[DEBUG]: Reading from /etc/ssh/sshd_config (quiet=False)
2021-08-15 16:56:38,525 - util.py[DEBUG]: Read 3291 bytes from /etc/ssh/sshd_config
2021-08-15 16:56:38,525 - handlers.py[DEBUG]: finish: modules-final/config-ssh-authkey-fingerprints: SUCCESS: config-ssh-authkey-fingerprints ran successfully
2021-08-15 16:56:38,525 - stages.py[DEBUG]: Running module keys-to-console (<module 'cloudinit.config.cc_keys_to_console' from '/usr/lib/python3/dist-packages/cloudinit/config/cc_keys_to_console.py'>) with frequency once-per-instance
2021-08-15 16:56:38,526 - handlers.py[DEBUG]: start: modules-final/config-keys-to-console: running config-keys-to-console with frequency once-per-instance
2021-08-15 16:56:38,526 - util.py[DEBUG]: Writing to /var/lib/cloud/instances/iid-datasource-none/sem/config_keys_to_console - wb: [644] 24 bytes
2021-08-15 16:56:38,526 - helpers.py[DEBUG]: Running config-keys-to-console using lock (<FileLock using file '/var/lib/cloud/instances/iid-datasource-none/sem/config_keys_to_console'>)
2021-08-15 16:56:38,526 - util.py[DEBUG]: Running command ['/usr/lib/cloud-init/write-ssh-key-fingerprints', '', 'ssh-dss'] with allowed return codes [0] (shell=False, capture=True)
2021-08-15 16:56:38,544 - handlers.py[DEBUG]: finish: modules-final/config-keys-to-console: SUCCESS: config-keys-to-console ran successfully
2021-08-15 16:56:38,545 - stages.py[DEBUG]: Running module phone-home (<module 'cloudinit.config.cc_phone_home' from '/usr/lib/python3/dist-packages/cloudinit/config/cc_phone_home.py'>) with frequency once-per-instance
2021-08-15 16:56:38,545 - handlers.py[DEBUG]: start: modules-final/config-phone-home: running config-phone-home with frequency once-per-instance
2021-08-15 16:56:38,545 - util.py[DEBUG]: Writing to /var/lib/cloud/instances/iid-datasource-none/sem/config_phone_home - wb: [644] 25 bytes
2021-08-15 16:56:38,545 - helpers.py[DEBUG]: Running config-phone-home using lock (<FileLock using file '/var/lib/cloud/instances/iid-datasource-none/sem/config_phone_home'>)
2021-08-15 16:56:38,546 - cc_phone_home.py[DEBUG]: Skipping module named phone-home, no 'phone_home' configuration found
2021-08-15 16:56:38,546 - handlers.py[DEBUG]: finish: modules-final/config-phone-home: SUCCESS: config-phone-home ran successfully
2021-08-15 16:56:38,546 - stages.py[DEBUG]: Running module final-message (<module 'cloudinit.config.cc_final_message' from '/usr/lib/python3/dist-packages/cloudinit/config/cc_final_message.py'>) with frequency always
2021-08-15 16:56:38,546 - handlers.py[DEBUG]: start: modules-final/config-final-message: running config-final-message with frequency always
2021-08-15 16:56:38,546 - helpers.py[DEBUG]: Running config-final-message using lock (<cloudinit.helpers.DummyLock object at 0x7eff59913e10>)
2021-08-15 16:56:38,546 - util.py[DEBUG]: Reading from /proc/uptime (quiet=False)
2021-08-15 16:56:38,546 - util.py[DEBUG]: Read 11 bytes from /proc/uptime
2021-08-15 16:56:38,549 - util.py[DEBUG]: Cloud-init v. 20.2-45-g5f7825e2-0ubuntu1~18.04.1 finished at Sun, 15 Aug 2021 16:56:38 +0000. Datasource DataSourceNone.  Up 18.93 seconds
2021-08-15 16:56:38,549 - util.py[DEBUG]: Writing to /var/lib/cloud/instance/boot-finished - wb: [644] 80 bytes
2021-08-15 16:56:38,550 - cc_final_message.py[WARNING]: Used fallback datasource
2021-08-15 16:56:38,550 - handlers.py[DEBUG]: finish: modules-final/config-final-message: SUCCESS: config-final-message ran successfully
2021-08-15 16:56:38,550 - stages.py[DEBUG]: Running module power-state-change (<module 'cloudinit.config.cc_power_state_change' from '/usr/lib/python3/dist-packages/cloudinit/config/cc_power_state_change.py'>) with frequency once-per-instance
2021-08-15 16:56:38,551 - handlers.py[DEBUG]: start: modules-final/config-power-state-change: running config-power-state-change with frequency once-per-instance
2021-08-15 16:56:38,551 - util.py[DEBUG]: Writing to /var/lib/cloud/instances/iid-datasource-none/sem/config_power_state_change - wb: [644] 25 bytes
2021-08-15 16:56:38,551 - helpers.py[DEBUG]: Running config-power-state-change using lock (<FileLock using file '/var/lib/cloud/instances/iid-datasource-none/sem/config_power_state_change'>)
2021-08-15 16:56:38,551 - cc_power_state_change.py[DEBUG]: no power_state provided. doing nothing
2021-08-15 16:56:38,551 - handlers.py[DEBUG]: finish: modules-final/config-power-state-change: SUCCESS: config-power-state-change ran successfully
2021-08-15 16:56:38,551 - main.py[DEBUG]: Ran 20 modules with 0 failures
2021-08-15 16:56:38,552 - atomic_helper.py[DEBUG]: Atomically writing to file /var/lib/cloud/data/status.json (via temporary file /var/lib/cloud/data/tmprguuu256) - w: [644] 568 bytes/chars
2021-08-15 16:56:38,552 - atomic_helper.py[DEBUG]: Atomically writing to file /var/lib/cloud/data/result.json (via temporary file /var/lib/cloud/data/tmpe4fydxz5) - w: [644] 65 bytes/chars
2021-08-15 16:56:38,552 - util.py[DEBUG]: Creating symbolic link from '/run/cloud-init/result.json' => '../../var/lib/cloud/data/result.json'
2021-08-15 16:56:38,552 - util.py[DEBUG]: Reading from /proc/uptime (quiet=False)
2021-08-15 16:56:38,552 - util.py[DEBUG]: Read 11 bytes from /proc/uptime
2021-08-15 16:56:38,552 - util.py[DEBUG]: cloud-init mode 'modules' took 0.140 seconds (0.14)
2021-08-15 16:56:38,553 - handlers.py[DEBUG]: finish: modules-final: SUCCESS: running modules for final
